Workbook

Sheet data
A1: icons | B1: value | C1: col3 | D1: col4 | E1: col5
A2: =[1]data!$C$2 -> Tobacco Use
A3: =[1]data!$C$3 -> of the population are current smokers | B3: =[1]data!$D$3 -> 0.10764758 | C3: =(B3*100) -> 10.764758 | D3: =100-C3 -> 89.235242
A4: =[1]data!$C$4 -> of men | B4: =[1]data!$D$4 -> 0.16435643 | C4: =ROUND(B4*100,1) -> 16.4 | D4: =100-C4 -> 83.6 | E4: =TEXT(B4, "0% ")& CHAR(10) & A4 -> 16% of men
A5: =[1]data!$C$5 -> of women | B5: =[1]data!$D$5 -> 0.0039214223 | C5: =ROUND(B5*100,1) -> 0.4 | D5: =100-C5 -> 99.6 | E5: =IF(C5<1,_xlfn.CONCAT("<1% ", A5),TEXT(B5, "0% ")& CHAR(10) & A5) -> <1% of women
A6: =[1]data!$C$6 -> Among current smokers
A7: =[1]data!$C$7 -> smoke daily | B7: =[1]data!$D$7 -> 0.77429235 | C7: =(B7*100) -> 77.429235 | D7: =100-C7 -> 22.570765
A8: =[1]data!$C$8 -> smoke manufactured cigarettes | B8: =[1]data!$D$8 -> 0.82515702 | C8: =(B8*100) -> 82.515702 | D8: =100-C8 -> 17.484298
A9: =[1]data!$C$9 -> smoke hand-rolled cigarettes | B9: =[1]data!$D$9 -> 0.15418665 | C9: =(B9*100) -> 15.418665 | D9: =100-C9 -> 84.581335
A10: =[1]data!$C$10 -> smoke cigars, cheroots or cigarillos | B10: =[1]data!$D$10 -> 0.095096433 | C10: =(B10*100) -> 9.5096433 | D10: =100-C10 -> 90.490357
A11: =[1]data!$C$11 -> smoke pipes | B11: =[1]data!$D$11 -> 0.15843615 | C11: =(B11*100) -> 15.843615 | D11: =100-C11 -> 84.156385
A12: =[1]data!$C$12 -> smoke shisha | B12: =[1]data!$D$12 -> 0.15247962 | C12: =(B12*100) -> 15.247962 | D12: =100-C12 -> 84.752038
A13: =[1]data!$C$13 -> have tried to stop smoking during the past 12 months | B13: =[1]data!$D$13 -> 0.41549284 | C13: =(B13*100) -> 41.549284 | D13: =100-C13 -> 58.450716 | E13: =TEXT(data!B13, "0% ") & CHAR(10) & A13 -> 42% have tried to stop smoking during the past 12 months
A14: =[1]data!$C$14 -> have been advised by a health care professional to stop smoking | B14: =[1]data!$D$14 -> 0.35521876 | C14: =(B14*100) -> 35.521876 | D14: =100-C14 -> 64.478124 | E14: =TEXT(data!B14, "0% ") & CHAR(10) & A14 -> 36% have been advised by a health care professional to stop smoking
A15: =[1]data!$C$15 -> of the population are current smokeless users | B15: =[1]data!$D$15 -> 0.012447157 | C15: =(B15*100) -> 1.2447157 | D15: =100-C15 -> 98.755284
A16: =[1]data!$C$16 -> of the population currently use any tobacco products | B16: =[1]data!$D$16 -> 0.11498829 | C16: =(B16*100) -> 11.498829 | D16: =100-C16 -> 88.501171
A18: =[1]data!$C$18 -> Alcohol Use
A19: =[1]data!$C$19 -> of the population are current drinkers | B19: =[1]data!$D$19 -> 0.014477028 | C19: =B19*100 -> 1.4477028 | D19: =100-C19 -> 98.552297
A20: =[1]data!$C$20 -> of men | B20: =[1]data!$D$20 -> 0.020592589 | C20: =ROUND(B20*100,1) -> 2.1 | D20: =100-C20 -> 97.9 | E20: =TEXT(B20, "0% ")& CHAR(10) & A20 -> 2% of men
A21: =[1]data!$C$21 -> of women | B21: =[1]data!$D$21 -> 0.0032910538 | C21: =ROUND(B21*100,1) -> 0.3 | D21: =100-C21 -> 99.7 | E21: =TEXT(B21, "0% ")& CHAR(10) & A21 -> 0% of women
A22: =[1]data!$C$22 -> of 18-44 years | B22: =[1]data!$D$22 -> 0.015221667 | C22: =ROUND(B22*100,1) -> 1.5 | D22: =100-C22 -> 98.5 | E22: =TEXT(B22, "0% ")& CHAR(10) & A22 -> 2% of 18-44 years
A23: =[1]data!$C$23 -> of 45-69 years | B23: =[1]data!$D$23 -> 0.015992951 | C23: =ROUND(B23*100,1) -> 1.6 | D23: =100-C23 -> 98.4 | E23: =TEXT(B23, "0% ")& CHAR(10) & A23 -> 2% of 45-69 years
A24: =[1]data!$C$24 -> are current drinkers
A25: =[1]data!$C$25 -> of the population are lifetime abstainers | B25: =[1]data!$D$25 -> 0.96305317 | C25: =ROUND(B25*100,1) -> 96.3 | D25: =100-C25 -> 3.7
A26: =[1]data!$C$26 -> Heavy episodic drinking
A27: =[1]data!$C$27 -> of the population consumed 6 or more drinks on one occasion in the past 30 days | B27: =[1]data!$D$27 -> 0.00083692475
A28: =[1]data!$C$28 -> of men consumed 6 or more drinks on one occasion | B28: =[1]data!$D$28 -> 0.001295305
A29: =[1]data!$C$29 -> of women consumed 6 or more drinks on one occasion | B29: =[1]data!$D$29 -> 2.3420318e-12
A31: =[1]data!$C$31 -> Diet
A32: =[1]data!$C$32 -> days
A33: =[1]data!$C$33 -> mean number of days fruits are consumed in a typical week | B33: =ROUND([1]data!$D$33,1) -> 4.6 | C33: =B33*100/7 -> 65.714286
A34: =[1]data!$C$34 -> mean number of days vegetables consumed in a typical week | B34: =ROUND([1]data!$D$34,1) -> 5.6 | C34: =B34*100/7 -> 80
A35: =[1]data!$C$35 -> of the population eat less than 5 servings of fruit and/or vegetables per day | B35: =[1]data!$D$35 -> 0.64835113 | C35: =ROUND(B35*100,0) -> 65 | D35: =100-C35 -> 35
A36: =[1]data!$C$36 -> of the population do not eat any fruit or vegetables | B36: =[1]data!$D$36 -> 0.081973192 | C36: =B36*100 -> 8.1973192 | D36: =100-C36 -> 91.802681 | E36: =TEXT(data!B36, "0% ") & CHAR(10) & A36 -> 8% of the population do not eat any fruit or vegetables
A37: =[1]data!$C$37 -> of the population always or often eat processed foods high in salt | B37: =[1]data!$D$37 -> 0.15486218 | C37: =B37*100 -> 15.486218 | D37: =100-C37 -> 84.513782
A38: =[1]data!$C$38 -> mean number of grams of salt consumed per day | B38: =[1]data!$D$38 -> 8.5724624 | C38: =_xlfn.CONCAT(B38) -> 8.5724624149887
A40: =[1]data!$C$40 -> Physical Activity
A41: =[1]data!$C$41 -> of the population are not meeting WHO's recommendation for physical activity | B41: =[1]data!$D$41 -> 0.28218007 | C41: =B41*100 -> 28.218007 | D41: =100-C41 -> 71.781993
A42: =[1]data!$C$42 -> Among women …
A43: =[1]data!$C$43 -> Among men …
...

Sheet Tobacco
B2: =data!A2 -> Tobacco Use
B8: =data!B3 -> 0.10764758
D32: =data!B15 -> 0.012447157

Sheet Alcohol Use
B2: =data!A18 -> Alcohol Use

Sheet Diet
B2: =data!A31 -> Diet
B5: =data!B33 & data!A32 -> 4.6 days
B11: =data!B34 & data!A32 -> 5.6 days

Sheet Physical Activity
B2: =data!A40 -> Physical Activity

Sheet BMI
A2: =data!A55 -> Body Mass Index

Sheet Raised blood pressure
A1: =data!A65 -> Raised Blood Pressure

Sheet Diabetes
A2: =data!A73 -> Raised Blood Sugar

Sheet Raised cholesterol
A1: =data!A79 -> Raised Total Cholesterol

Sheet Cardiovascular disease
A2: =data!A87 -> Cardiovascular Disease

Sheet Lifestyle advice
B2: =data!A92 -> Lifestyle Advice*

Sheet Multiple risk factors
B1: =data!A102 -> Multiple Risk Factors
